INFO _internal.py:122  * Restarting with stat
WARNING _internal.py:122  * Debugger is active!
INFO _internal.py:122  * Debugger PIN: 914-416-753
INFO _internal.py:122  * Running on http://127.0.0.1:5000/ (Press CTRL+C to quit)
ERROR demo.py:8 出错了
INFO _internal.py:122 127.0.0.1 - - [30/May/2019 11:10:50] "GET /api/V1.0/index HTTP/1.1" 200 -
ERROR demo.py:8 出错了
INFO _internal.py:122 127.0.0.1 - - [30/May/2019 11:10:51] "GET /api/V1.0/index HTTP/1.1" 200 -
INFO _internal.py:122  * Running on http://127.0.0.1:5000/ (Press CTRL+C to quit)
ERROR demo.py:8 出错了
INFO _internal.py:122 127.0.0.1 - - [30/May/2019 11:45:44] "GET /api/V1.0/index HTTP/1.1" 200 -
ERROR demo.py:8 出错了
INFO _internal.py:122 127.0.0.1 - - [30/May/2019 11:45:45] "GET /api/V1.0/index HTTP/1.1" 200 -
INFO _internal.py:122  * Running on http://127.0.0.1:5000/ (Press CTRL+C to quit)
INFO _internal.py:122  * Running on http://127.0.0.1:5000/ (Press CTRL+C to quit)
INFO _internal.py:122  * Running on http://127.0.0.1:5000/ (Press CTRL+C to quit)
INFO _internal.py:88  * Running on http://127.0.0.1:5000/ (Press CTRL+C to quit)
ERROR __init__.py:97 Error: Path doesn't exist: 'migrations'.  Please use the 'init' command to create a new scripts folder.
INFO _internal.py:88  * Running on http://127.0.0.1:5000/ (Press CTRL+C to quit)
INFO _internal.py:88  * Running on http://127.0.0.1:5000/ (Press CTRL+C to quit)
INFO _internal.py:88 127.0.0.1 - - [30/May/2019 15:15:57] "GET /api/V1.0/index.html HTTP/1.1" 404 -
INFO _internal.py:88 127.0.0.1 - - [30/May/2019 15:16:00] "GET /api/V1.0/index.html HTTP/1.1" 404 -
ERROR demo.py:11 出错了
INFO _internal.py:88 127.0.0.1 - - [30/May/2019 15:16:32] "GET /api/V1.0/index HTTP/1.1" 200 -
INFO _internal.py:88 127.0.0.1 - - [30/May/2019 15:16:46] "GET /static/html/index.html HTTP/1.1" 200 -
INFO _internal.py:88 127.0.0.1 - - [30/May/2019 15:16:46] "GET /static/plugins/bootstrap/css/bootstrap.min.css HTTP/1.1" 200 -
INFO _internal.py:88 127.0.0.1 - - [30/May/2019 15:16:46] "GET /static/plugins/font-awesome/css/font-awesome.min.css HTTP/1.1" 200 -
INFO _internal.py:88 127.0.0.1 - - [30/May/2019 15:16:46] "GET /static/css/reset.css HTTP/1.1" 200 -
INFO _internal.py:88 127.0.0.1 - - [30/May/2019 15:16:46] "GET /static/plugins/swiper/css/swiper.min.css HTTP/1.1" 200 -
INFO _internal.py:88 127.0.0.1 - - [30/May/2019 15:16:46] "GET /static/plugins/bootstrap-datepicker/css/bootstrap-datepicker.min.css HTTP/1.1" 200 -
INFO _internal.py:88 127.0.0.1 - - [30/May/2019 15:16:46] "GET /static/css/ihome/main.css HTTP/1.1" 200 -
INFO _internal.py:88 127.0.0.1 - - [30/May/2019 15:16:46] "GET /static/css/ihome/index.css HTTP/1.1" 200 -
INFO _internal.py:88 127.0.0.1 - - [30/May/2019 15:16:46] "GET /static/images/logo@128x59.png HTTP/1.1" 200 -
INFO _internal.py:88 127.0.0.1 - - [30/May/2019 15:16:46] "GET /static/images/home01.jpg HTTP/1.1" 200 -
INFO _internal.py:88 127.0.0.1 - - [30/May/2019 15:16:46] "GET /static/js/jquery.min.js HTTP/1.1" 200 -
INFO _internal.py:88 127.0.0.1 - - [30/May/2019 15:16:46] "GET /static/plugins/bootstrap/js/bootstrap.min.js HTTP/1.1" 200 -
INFO _internal.py:88 127.0.0.1 - - [30/May/2019 15:16:46] "GET /static/plugins/swiper/js/swiper.jquery.min.js HTTP/1.1" 200 -
INFO _internal.py:88 127.0.0.1 - - [30/May/2019 15:16:46] "GET /static/plugins/bootstrap-datepicker/js/bootstrap-datepicker.min.js HTTP/1.1" 200 -
INFO _internal.py:88 127.0.0.1 - - [30/May/2019 15:16:46] "GET /static/plugins/bootstrap-datepicker/locales/bootstrap-datepicker.zh-CN.min.js HTTP/1.1" 200 -
INFO _internal.py:88 127.0.0.1 - - [30/May/2019 15:16:46] "GET /static/js/template.js HTTP/1.1" 200 -
INFO _internal.py:88 127.0.0.1 - - [30/May/2019 15:16:47] "GET /static/js/ihome/index.js HTTP/1.1" 200 -
INFO _internal.py:88 127.0.0.1 - - [30/May/2019 15:16:47] "GET /static/images/home03.jpg HTTP/1.1" 200 -
INFO _internal.py:88 127.0.0.1 - - [30/May/2019 15:16:47] "GET /static/images/home02.jpg HTTP/1.1" 200 -
INFO _internal.py:88 127.0.0.1 - - [30/May/2019 15:16:47] "GET /static/plugins/font-awesome/fonts/fontawesome-webfont.woff2?v=4.6.3 HTTP/1.1" 200 -
INFO _internal.py:88 127.0.0.1 - - [30/May/2019 15:16:55] "GET /login.html HTTP/1.1" 404 -
INFO _internal.py:88  * Running on http://127.0.0.1:5000/ (Press CTRL+C to quit)
INFO _internal.py:88 127.0.0.1 - - [30/May/2019 16:05:54] "GET /static/html/index.html HTTP/1.1" 304 -
INFO _internal.py:88 127.0.0.1 - - [30/May/2019 16:05:58] "GET /static/html/ HTTP/1.1" 404 -
INFO _internal.py:88 127.0.0.1 - - [30/May/2019 16:06:01] "GET /static/html/ HTTP/1.1" 404 -
INFO _internal.py:88 127.0.0.1 - - [30/May/2019 16:06:19] "GET /static/html/my HTTP/1.1" 404 -
INFO _internal.py:88 127.0.0.1 - - [30/May/2019 16:06:19] "GET /static/html/auth.html HTTP/1.1" 200 -
INFO _internal.py:88 127.0.0.1 - - [30/May/2019 16:06:19] "GET /static/css/ihome/profile.css HTTP/1.1" 200 -
INFO _internal.py:88 127.0.0.1 - - [30/May/2019 16:06:19] "GET /static/js/jquery.form.min.js HTTP/1.1" 200 -
INFO _internal.py:88 127.0.0.1 - - [30/May/2019 16:06:19] "GET /static/js/ihome/auth.js HTTP/1.1" 200 -
INFO _internal.py:88  * Running on http://127.0.0.1:5000/ (Press CTRL+C to quit)
INFO _internal.py:88 127.0.0.1 - - [30/May/2019 16:06:58] "GET /static/html/ HTTP/1.1" 404 -
INFO _internal.py:88 127.0.0.1 - - [30/May/2019 16:07:00] "GET /static/html/ HTTP/1.1" 404 -
INFO _internal.py:88 127.0.0.1 - - [30/May/2019 16:08:24] "GET /auth.html HTTP/1.1" 404 -
INFO _internal.py:88 127.0.0.1 - - [30/May/2019 16:08:48] "GET /auth.html HTTP/1.1" 404 -
INFO _internal.py:88 127.0.0.1 - - [30/May/2019 16:08:51] "GET /auth.html HTTP/1.1" 404 -
INFO _internal.py:88 127.0.0.1 - - [30/May/2019 16:08:53] "GET /auth.html HTTP/1.1" 404 -
INFO _internal.py:88  * Running on http://127.0.0.1:5000/ (Press CTRL+C to quit)
INFO _internal.py:88 127.0.0.1 - - [30/May/2019 16:12:02] "GET /auth.html HTTP/1.1" 200 -
INFO _internal.py:88 127.0.0.1 - - [30/May/2019 16:12:02] "GET /static/plugins/bootstrap/css/bootstrap.min.css HTTP/1.1" 200 -
INFO _internal.py:88 127.0.0.1 - - [30/May/2019 16:12:02] "GET /static/plugins/font-awesome/css/font-awesome.min.css HTTP/1.1" 200 -
INFO _internal.py:88 127.0.0.1 - - [30/May/2019 16:12:02] "GET /static/css/reset.css HTTP/1.1" 200 -
INFO _internal.py:88 127.0.0.1 - - [30/May/2019 16:12:02] "GET /static/css/ihome/profile.css HTTP/1.1" 200 -
INFO _internal.py:88 127.0.0.1 - - [30/May/2019 16:12:02] "GET /static/css/ihome/main.css HTTP/1.1" 200 -
INFO _internal.py:88 127.0.0.1 - - [30/May/2019 16:12:02] "GET /static/plugins/bootstrap-datepicker/css/bootstrap-datepicker.min.css HTTP/1.1" 200 -
INFO _internal.py:88 127.0.0.1 - - [30/May/2019 16:12:02] "GET /static/js/jquery.min.js HTTP/1.1" 200 -
INFO _internal.py:88 127.0.0.1 - - [30/May/2019 16:12:02] "GET /static/js/jquery.form.min.js HTTP/1.1" 200 -
INFO _internal.py:88 127.0.0.1 - - [30/May/2019 16:12:02] "GET /static/plugins/bootstrap/js/bootstrap.min.js HTTP/1.1" 200 -
INFO _internal.py:88 127.0.0.1 - - [30/May/2019 16:12:02] "GET /static/plugins/bootstrap-datepicker/js/bootstrap-datepicker.min.js HTTP/1.1" 200 -
INFO _internal.py:88 127.0.0.1 - - [30/May/2019 16:12:02] "GET /static/plugins/bootstrap-datepicker/locales/bootstrap-datepicker.zh-CN.min.js HTTP/1.1" 200 -
INFO _internal.py:88 127.0.0.1 - - [30/May/2019 16:12:02] "GET /static/js/ihome/auth.js HTTP/1.1" 200 -
INFO _internal.py:88 127.0.0.1 - - [30/May/2019 16:12:02] "GET /static/plugins/font-awesome/fonts/fontawesome-webfont.woff2?v=4.6.3 HTTP/1.1" 200 -
INFO _internal.py:88 127.0.0.1 - - [30/May/2019 16:12:06] "GET / HTTP/1.1" 200 -
INFO _internal.py:88 127.0.0.1 - - [30/May/2019 16:12:06] "GET /static/plugins/swiper/css/swiper.min.css HTTP/1.1" 200 -
INFO _internal.py:88 127.0.0.1 - - [30/May/2019 16:12:06] "GET /static/css/ihome/index.css HTTP/1.1" 200 -
INFO _internal.py:88 127.0.0.1 - - [30/May/2019 16:12:06] "GET /static/images/logo@128x59.png HTTP/1.1" 200 -
INFO _internal.py:88 127.0.0.1 - - [30/May/2019 16:12:06] "GET /static/images/home01.jpg HTTP/1.1" 200 -
INFO _internal.py:88 127.0.0.1 - - [30/May/2019 16:12:06] "GET /static/plugins/swiper/js/swiper.jquery.min.js HTTP/1.1" 200 -
INFO _internal.py:88 127.0.0.1 - - [30/May/2019 16:12:06] "GET /static/js/template.js HTTP/1.1" 200 -
INFO _internal.py:88 127.0.0.1 - - [30/May/2019 16:12:06] "GET /static/js/ihome/index.js HTTP/1.1" 200 -
INFO _internal.py:88 127.0.0.1 - - [30/May/2019 16:12:06] "GET /static/images/home02.jpg HTTP/1.1" 200 -
INFO _internal.py:88 127.0.0.1 - - [30/May/2019 16:12:06] "GET /static/images/home03.jpg HTTP/1.1" 200 -
INFO _internal.py:88 127.0.0.1 - - [30/May/2019 16:12:12] "GET /register HTTP/1.1" 404 -
INFO _internal.py:88 127.0.0.1 - - [30/May/2019 16:12:19] "GET /my HTTP/1.1" 404 -
INFO _internal.py:88 127.0.0.1 - - [30/May/2019 16:12:33] "GET /my.html HTTP/1.1" 200 -
INFO _internal.py:88 127.0.0.1 - - [30/May/2019 16:12:33] "GET /static/css/ihome/my.css HTTP/1.1" 200 -
INFO _internal.py:88 127.0.0.1 - - [30/May/2019 16:12:33] "GET /static/js/ihome/my.js HTTP/1.1" 200 -
INFO _internal.py:88 127.0.0.1 - - [30/May/2019 17:35:40] "GET /my.html HTTP/1.1" 304 -
INFO _internal.py:88 127.0.0.1 - - [30/May/2019 17:35:49] "GET /search.html?aid=&aname=&sd=&ed= HTTP/1.1" 200 -
INFO _internal.py:88 127.0.0.1 - - [30/May/2019 17:35:49] "GET /static/css/ihome/search.css HTTP/1.1" 200 -
INFO _internal.py:88 127.0.0.1 - - [30/May/2019 17:35:49] "GET /static/js/ihome/search.js HTTP/1.1" 200 -
INFO _internal.py:88 127.0.0.1 - - [30/May/2019 17:35:50] "GET /static/images/landlord01.jgp HTTP/1.1" 404 -
INFO _internal.py:88 127.0.0.1 - - [30/May/2019 17:36:10] "GET /static/plugins/bootstrap/css/bootstrap.min.css.map HTTP/1.1" 200 -
INFO _internal.py:88  * Running on http://127.0.0.1:5000/ (Press CTRL+C to quit)
INFO _internal.py:88  * Running on http://127.0.0.1:5000/ (Press CTRL+C to quit)
ERROR app.py:1761 Exception on / [GET]
Traceback (most recent call last):
  File "D:\Program\Python37\lib\site-packages\redis\connection.py", line 492, in connect
    sock = self._connect()
  File "D:\Program\Python37\lib\site-packages\redis\connection.py", line 550, in _connect
    raise err
  File "D:\Program\Python37\lib\site-packages\redis\connection.py", line 538, in _connect
    sock.connect(socket_address)
TimeoutError: [WinError 10060] 由于连接方在一段时间后没有正确答复或连接的主机没有反应，连接尝试失败。

During handling of the above exception, another exception occurred:

Traceback (most recent call last):
  File "D:\Program\Python37\lib\site-packages\flask\app.py", line 2291, in wsgi_app
    ctx.push()
  File "D:\Program\Python37\lib\site-packages\flask\ctx.py", line 377, in push
    self.app, self.request
  File "D:\Program\Python37\lib\site-packages\flask_session\sessions.py", line 132, in open_session
    val = self.redis.get(self.key_prefix + sid)
  File "D:\Program\Python37\lib\site-packages\redis\client.py", line 1264, in get
    return self.execute_command('GET', name)
  File "D:\Program\Python37\lib\site-packages\redis\client.py", line 772, in execute_command
    connection = pool.get_connection(command_name, **options)
  File "D:\Program\Python37\lib\site-packages\redis\connection.py", line 994, in get_connection
    connection.connect()
  File "D:\Program\Python37\lib\site-packages\redis\connection.py", line 497, in connect
    raise ConnectionError(self._error_message(e))
redis.exceptions.ConnectionError: Error 10060 connecting to 192.168.99.100:6379. 由于连接方在一段时间后没有正确答复或连接的主机没有反应，连接尝试失败。.
INFO _internal.py:88 127.0.0.1 - - [31/May/2019 14:24:09] "GET / HTTP/1.1" 500 -
ERROR app.py:1761 Exception on /favicon.ico [GET]
Traceback (most recent call last):
  File "D:\Program\Python37\lib\site-packages\redis\connection.py", line 492, in connect
    sock = self._connect()
  File "D:\Program\Python37\lib\site-packages\redis\connection.py", line 550, in _connect
    raise err
  File "D:\Program\Python37\lib\site-packages\redis\connection.py", line 538, in _connect
    sock.connect(socket_address)
TimeoutError: [WinError 10060] 由于连接方在一段时间后没有正确答复或连接的主机没有反应，连接尝试失败。

During handling of the above exception, another exception occurred:

Traceback (most recent call last):
  File "D:\Program\Python37\lib\site-packages\flask\app.py", line 2291, in wsgi_app
    ctx.push()
  File "D:\Program\Python37\lib\site-packages\flask\ctx.py", line 377, in push
    self.app, self.request
  File "D:\Program\Python37\lib\site-packages\flask_session\sessions.py", line 132, in open_session
    val = self.redis.get(self.key_prefix + sid)
  File "D:\Program\Python37\lib\site-packages\redis\client.py", line 1264, in get
    return self.execute_command('GET', name)
  File "D:\Program\Python37\lib\site-packages\redis\client.py", line 772, in execute_command
    connection = pool.get_connection(command_name, **options)
  File "D:\Program\Python37\lib\site-packages\redis\connection.py", line 994, in get_connection
    connection.connect()
  File "D:\Program\Python37\lib\site-packages\redis\connection.py", line 497, in connect
    raise ConnectionError(self._error_message(e))
redis.exceptions.ConnectionError: Error 10060 connecting to 192.168.99.100:6379. 由于连接方在一段时间后没有正确答复或连接的主机没有反应，连接尝试失败。.
INFO _internal.py:88 127.0.0.1 - - [31/May/2019 14:24:31] "GET /favicon.ico HTTP/1.1" 500 -
ERROR app.py:1761 Exception on / [GET]
Traceback (most recent call last):
  File "D:\Program\Python37\lib\site-packages\redis\connection.py", line 492, in connect
    sock = self._connect()
  File "D:\Program\Python37\lib\site-packages\redis\connection.py", line 550, in _connect
    raise err
  File "D:\Program\Python37\lib\site-packages\redis\connection.py", line 538, in _connect
    sock.connect(socket_address)
TimeoutError: [WinError 10060] 由于连接方在一段时间后没有正确答复或连接的主机没有反应，连接尝试失败。

During handling of the above exception, another exception occurred:

Traceback (most recent call last):
  File "D:\Program\Python37\lib\site-packages\flask\app.py", line 2291, in wsgi_app
    ctx.push()
  File "D:\Program\Python37\lib\site-packages\flask\ctx.py", line 377, in push
    self.app, self.request
  File "D:\Program\Python37\lib\site-packages\flask_session\sessions.py", line 132, in open_session
    val = self.redis.get(self.key_prefix + sid)
  File "D:\Program\Python37\lib\site-packages\redis\client.py", line 1264, in get
    return self.execute_command('GET', name)
  File "D:\Program\Python37\lib\site-packages\redis\client.py", line 772, in execute_command
    connection = pool.get_connection(command_name, **options)
  File "D:\Program\Python37\lib\site-packages\redis\connection.py", line 994, in get_connection
    connection.connect()
  File "D:\Program\Python37\lib\site-packages\redis\connection.py", line 497, in connect
    raise ConnectionError(self._error_message(e))
redis.exceptions.ConnectionError: Error 10060 connecting to 192.168.99.100:6379. 由于连接方在一段时间后没有正确答复或连接的主机没有反应，连接尝试失败。.
INFO _internal.py:88 127.0.0.1 - - [31/May/2019 14:31:42] "GET / HTTP/1.1" 500 -
ERROR app.py:1761 Exception on / [GET]
Traceback (most recent call last):
  File "D:\Program\Python37\lib\site-packages\redis\connection.py", line 492, in connect
    sock = self._connect()
  File "D:\Program\Python37\lib\site-packages\redis\connection.py", line 550, in _connect
    raise err
  File "D:\Program\Python37\lib\site-packages\redis\connection.py", line 538, in _connect
    sock.connect(socket_address)
TimeoutError: [WinError 10060] 由于连接方在一段时间后没有正确答复或连接的主机没有反应，连接尝试失败。

During handling of the above exception, another exception occurred:

Traceback (most recent call last):
  File "D:\Program\Python37\lib\site-packages\flask\app.py", line 2291, in wsgi_app
    ctx.push()
  File "D:\Program\Python37\lib\site-packages\flask\ctx.py", line 377, in push
    self.app, self.request
  File "D:\Program\Python37\lib\site-packages\flask_session\sessions.py", line 132, in open_session
    val = self.redis.get(self.key_prefix + sid)
  File "D:\Program\Python37\lib\site-packages\redis\client.py", line 1264, in get
    return self.execute_command('GET', name)
  File "D:\Program\Python37\lib\site-packages\redis\client.py", line 772, in execute_command
    connection = pool.get_connection(command_name, **options)
  File "D:\Program\Python37\lib\site-packages\redis\connection.py", line 994, in get_connection
    connection.connect()
  File "D:\Program\Python37\lib\site-packages\redis\connection.py", line 497, in connect
    raise ConnectionError(self._error_message(e))
redis.exceptions.ConnectionError: Error 10060 connecting to 192.168.99.100:6379. 由于连接方在一段时间后没有正确答复或连接的主机没有反应，连接尝试失败。.
INFO _internal.py:88 127.0.0.1 - - [31/May/2019 14:32:03] "GET / HTTP/1.1" 500 -
ERROR app.py:1761 Exception on /index [GET]
Traceback (most recent call last):
  File "D:\Program\Python37\lib\site-packages\redis\connection.py", line 492, in connect
    sock = self._connect()
  File "D:\Program\Python37\lib\site-packages\redis\connection.py", line 550, in _connect
    raise err
  File "D:\Program\Python37\lib\site-packages\redis\connection.py", line 538, in _connect
    sock.connect(socket_address)
TimeoutError: [WinError 10060] 由于连接方在一段时间后没有正确答复或连接的主机没有反应，连接尝试失败。

During handling of the above exception, another exception occurred:

Traceback (most recent call last):
  File "D:\Program\Python37\lib\site-packages\flask\app.py", line 2291, in wsgi_app
    ctx.push()
  File "D:\Program\Python37\lib\site-packages\flask\ctx.py", line 377, in push
    self.app, self.request
  File "D:\Program\Python37\lib\site-packages\flask_session\sessions.py", line 132, in open_session
    val = self.redis.get(self.key_prefix + sid)
  File "D:\Program\Python37\lib\site-packages\redis\client.py", line 1264, in get
    return self.execute_command('GET', name)
  File "D:\Program\Python37\lib\site-packages\redis\client.py", line 772, in execute_command
    connection = pool.get_connection(command_name, **options)
  File "D:\Program\Python37\lib\site-packages\redis\connection.py", line 994, in get_connection
    connection.connect()
  File "D:\Program\Python37\lib\site-packages\redis\connection.py", line 497, in connect
    raise ConnectionError(self._error_message(e))
redis.exceptions.ConnectionError: Error 10060 connecting to 192.168.99.100:6379. 由于连接方在一段时间后没有正确答复或连接的主机没有反应，连接尝试失败。.
INFO _internal.py:88 127.0.0.1 - - [31/May/2019 14:32:24] "GET /index HTTP/1.1" 500 -
ERROR app.py:1761 Exception on /index [GET]
Traceback (most recent call last):
  File "D:\Program\Python37\lib\site-packages\redis\connection.py", line 492, in connect
    sock = self._connect()
  File "D:\Program\Python37\lib\site-packages\redis\connection.py", line 550, in _connect
    raise err
  File "D:\Program\Python37\lib\site-packages\redis\connection.py", line 538, in _connect
    sock.connect(socket_address)
TimeoutError: [WinError 10060] 由于连接方在一段时间后没有正确答复或连接的主机没有反应，连接尝试失败。

During handling of the above exception, another exception occurred:

Traceback (most recent call last):
  File "D:\Program\Python37\lib\site-packages\flask\app.py", line 2291, in wsgi_app
    ctx.push()
  File "D:\Program\Python37\lib\site-packages\flask\ctx.py", line 377, in push
    self.app, self.request
  File "D:\Program\Python37\lib\site-packages\flask_session\sessions.py", line 132, in open_session
    val = self.redis.get(self.key_prefix + sid)
  File "D:\Program\Python37\lib\site-packages\redis\client.py", line 1264, in get
    return self.execute_command('GET', name)
  File "D:\Program\Python37\lib\site-packages\redis\client.py", line 772, in execute_command
    connection = pool.get_connection(command_name, **options)
  File "D:\Program\Python37\lib\site-packages\redis\connection.py", line 994, in get_connection
    connection.connect()
  File "D:\Program\Python37\lib\site-packages\redis\connection.py", line 497, in connect
    raise ConnectionError(self._error_message(e))
redis.exceptions.ConnectionError: Error 10060 connecting to 192.168.99.100:6379. 由于连接方在一段时间后没有正确答复或连接的主机没有反应，连接尝试失败。.
INFO _internal.py:88 127.0.0.1 - - [31/May/2019 14:33:21] "GET /index HTTP/1.1" 500 -
ERROR app.py:1761 Exception on /favicon.ico [GET]
Traceback (most recent call last):
  File "D:\Program\Python37\lib\site-packages\redis\connection.py", line 492, in connect
    sock = self._connect()
  File "D:\Program\Python37\lib\site-packages\redis\connection.py", line 550, in _connect
    raise err
  File "D:\Program\Python37\lib\site-packages\redis\connection.py", line 538, in _connect
    sock.connect(socket_address)
TimeoutError: [WinError 10060] 由于连接方在一段时间后没有正确答复或连接的主机没有反应，连接尝试失败。

During handling of the above exception, another exception occurred:

Traceback (most recent call last):
  File "D:\Program\Python37\lib\site-packages\flask\app.py", line 2291, in wsgi_app
    ctx.push()
  File "D:\Program\Python37\lib\site-packages\flask\ctx.py", line 377, in push
    self.app, self.request
  File "D:\Program\Python37\lib\site-packages\flask_session\sessions.py", line 132, in open_session
    val = self.redis.get(self.key_prefix + sid)
  File "D:\Program\Python37\lib\site-packages\redis\client.py", line 1264, in get
    return self.execute_command('GET', name)
  File "D:\Program\Python37\lib\site-packages\redis\client.py", line 772, in execute_command
    connection = pool.get_connection(command_name, **options)
  File "D:\Program\Python37\lib\site-packages\redis\connection.py", line 994, in get_connection
    connection.connect()
  File "D:\Program\Python37\lib\site-packages\redis\connection.py", line 497, in connect
    raise ConnectionError(self._error_message(e))
redis.exceptions.ConnectionError: Error 10060 connecting to 192.168.99.100:6379. 由于连接方在一段时间后没有正确答复或连接的主机没有反应，连接尝试失败。.
INFO _internal.py:88 127.0.0.1 - - [31/May/2019 14:33:43] "GET /favicon.ico HTTP/1.1" 500 -
INFO _internal.py:88  * Running on http://127.0.0.1:5000/ (Press CTRL+C to quit)
ERROR app.py:1761 Exception on /index [GET]
Traceback (most recent call last):
  File "D:\Program\Python37\lib\site-packages\flask\app.py", line 2291, in wsgi_app
    ctx.push()
  File "D:\Program\Python37\lib\site-packages\flask\ctx.py", line 377, in push
    self.app, self.request
  File "D:\Program\Python37\lib\site-packages\flask_session\sessions.py", line 132, in open_session
    val = self.redis.get(self.key_prefix + sid)
  File "D:\Program\Python37\lib\site-packages\redis\client.py", line 1264, in get
    return self.execute_command('GET', name)
  File "D:\Program\Python37\lib\site-packages\redis\client.py", line 772, in execute_command
    connection = pool.get_connection(command_name, **options)
  File "D:\Program\Python37\lib\site-packages\redis\connection.py", line 994, in get_connection
    connection.connect()
  File "D:\Program\Python37\lib\site-packages\redis\connection.py", line 502, in connect
    self.on_connect()
  File "D:\Program\Python37\lib\site-packages\redis\connection.py", line 570, in on_connect
    if nativestr(self.read_response()) != 'OK':
  File "D:\Program\Python37\lib\site-packages\redis\connection.py", line 642, in read_response
    raise response
redis.exceptions.ResponseError: Client sent AUTH, but no password is set
INFO _internal.py:88 127.0.0.1 - - [31/May/2019 14:35:24] "GET /index HTTP/1.1" 500 -
ERROR app.py:1761 Exception on /favicon.ico [GET]
Traceback (most recent call last):
  File "D:\Program\Python37\lib\site-packages\flask\app.py", line 2291, in wsgi_app
    ctx.push()
  File "D:\Program\Python37\lib\site-packages\flask\ctx.py", line 377, in push
    self.app, self.request
  File "D:\Program\Python37\lib\site-packages\flask_session\sessions.py", line 132, in open_session
    val = self.redis.get(self.key_prefix + sid)
  File "D:\Program\Python37\lib\site-packages\redis\client.py", line 1264, in get
    return self.execute_command('GET', name)
  File "D:\Program\Python37\lib\site-packages\redis\client.py", line 772, in execute_command
    connection = pool.get_connection(command_name, **options)
  File "D:\Program\Python37\lib\site-packages\redis\connection.py", line 994, in get_connection
    connection.connect()
  File "D:\Program\Python37\lib\site-packages\redis\connection.py", line 502, in connect
    self.on_connect()
  File "D:\Program\Python37\lib\site-packages\redis\connection.py", line 570, in on_connect
    if nativestr(self.read_response()) != 'OK':
  File "D:\Program\Python37\lib\site-packages\redis\connection.py", line 642, in read_response
    raise response
redis.exceptions.ResponseError: Client sent AUTH, but no password is set
INFO _internal.py:88 127.0.0.1 - - [31/May/2019 14:35:25] "GET /favicon.ico HTTP/1.1" 500 -
ERROR app.py:1761 Exception on /index [GET]
Traceback (most recent call last):
  File "D:\Program\Python37\lib\site-packages\flask\app.py", line 2291, in wsgi_app
    ctx.push()
  File "D:\Program\Python37\lib\site-packages\flask\ctx.py", line 377, in push
    self.app, self.request
  File "D:\Program\Python37\lib\site-packages\flask_session\sessions.py", line 132, in open_session
    val = self.redis.get(self.key_prefix + sid)
  File "D:\Program\Python37\lib\site-packages\redis\client.py", line 1264, in get
    return self.execute_command('GET', name)
  File "D:\Program\Python37\lib\site-packages\redis\client.py", line 772, in execute_command
    connection = pool.get_connection(command_name, **options)
  File "D:\Program\Python37\lib\site-packages\redis\connection.py", line 994, in get_connection
    connection.connect()
  File "D:\Program\Python37\lib\site-packages\redis\connection.py", line 502, in connect
    self.on_connect()
  File "D:\Program\Python37\lib\site-packages\redis\connection.py", line 570, in on_connect
    if nativestr(self.read_response()) != 'OK':
  File "D:\Program\Python37\lib\site-packages\redis\connection.py", line 642, in read_response
    raise response
redis.exceptions.ResponseError: Client sent AUTH, but no password is set
INFO _internal.py:88 127.0.0.1 - - [31/May/2019 14:35:27] "GET /index HTTP/1.1" 500 -
ERROR app.py:1761 Exception on /favicon.ico [GET]
Traceback (most recent call last):
  File "D:\Program\Python37\lib\site-packages\flask\app.py", line 2291, in wsgi_app
    ctx.push()
  File "D:\Program\Python37\lib\site-packages\flask\ctx.py", line 377, in push
    self.app, self.request
  File "D:\Program\Python37\lib\site-packages\flask_session\sessions.py", line 132, in open_session
    val = self.redis.get(self.key_prefix + sid)
  File "D:\Program\Python37\lib\site-packages\redis\client.py", line 1264, in get
    return self.execute_command('GET', name)
  File "D:\Program\Python37\lib\site-packages\redis\client.py", line 772, in execute_command
    connection = pool.get_connection(command_name, **options)
  File "D:\Program\Python37\lib\site-packages\redis\connection.py", line 994, in get_connection
    connection.connect()
  File "D:\Program\Python37\lib\site-packages\redis\connection.py", line 502, in connect
    self.on_connect()
  File "D:\Program\Python37\lib\site-packages\redis\connection.py", line 570, in on_connect
    if nativestr(self.read_response()) != 'OK':
  File "D:\Program\Python37\lib\site-packages\redis\connection.py", line 642, in read_response
    raise response
redis.exceptions.ResponseError: Client sent AUTH, but no password is set
INFO _internal.py:88 127.0.0.1 - - [31/May/2019 14:35:27] "GET /favicon.ico HTTP/1.1" 500 -
INFO _internal.py:88  * Running on http://127.0.0.1:5000/ (Press CTRL+C to quit)
INFO _internal.py:88 127.0.0.1 - - [31/May/2019 14:37:25] "GET /index HTTP/1.1" 404 -
ERROR app.py:1761 Exception on /favicon.ico [GET]
Traceback (most recent call last):
  File "D:\Program\Python37\lib\site-packages\flask\app.py", line 2292, in wsgi_app
    response = self.full_dispatch_request()
  File "D:\Program\Python37\lib\site-packages\flask\app.py", line 1815, in full_dispatch_request
    rv = self.handle_user_exception(e)
  File "D:\Program\Python37\lib\site-packages\flask\app.py", line 1718, in handle_user_exception
    reraise(exc_type, exc_value, tb)
  File "D:\Program\Python37\lib\site-packages\flask\_compat.py", line 35, in reraise
    raise value
  File "D:\Program\Python37\lib\site-packages\flask\app.py", line 1813, in full_dispatch_request
    rv = self.dispatch_request()
  File "D:\Program\Python37\lib\site-packages\flask\app.py", line 1799, in dispatch_request
    return self.view_functions[rule.endpoint](**req.view_args)
  File "C:\Users\top\PycharmProjects\Ihome\ihome\web_html.py", line 18, in get_html
    resp.Set_cookie("csrf_token",csrf_token)
AttributeError: 'Response' object has no attribute 'Set_cookie'
INFO _internal.py:88 127.0.0.1 - - [31/May/2019 14:37:26] "GET /favicon.ico HTTP/1.1" 500 -
INFO _internal.py:88 127.0.0.1 - - [31/May/2019 14:37:28] "GET /index HTTP/1.1" 404 -
ERROR app.py:1761 Exception on /favicon.ico [GET]
Traceback (most recent call last):
  File "D:\Program\Python37\lib\site-packages\flask\app.py", line 2292, in wsgi_app
    response = self.full_dispatch_request()
  File "D:\Program\Python37\lib\site-packages\flask\app.py", line 1815, in full_dispatch_request
    rv = self.handle_user_exception(e)
  File "D:\Program\Python37\lib\site-packages\flask\app.py", line 1718, in handle_user_exception
    reraise(exc_type, exc_value, tb)
  File "D:\Program\Python37\lib\site-packages\flask\_compat.py", line 35, in reraise
    raise value
  File "D:\Program\Python37\lib\site-packages\flask\app.py", line 1813, in full_dispatch_request
    rv = self.dispatch_request()
  File "D:\Program\Python37\lib\site-packages\flask\app.py", line 1799, in dispatch_request
    return self.view_functions[rule.endpoint](**req.view_args)
  File "C:\Users\top\PycharmProjects\Ihome\ihome\web_html.py", line 18, in get_html
    resp.Set_cookie("csrf_token",csrf_token)
AttributeError: 'Response' object has no attribute 'Set_cookie'
INFO _internal.py:88 127.0.0.1 - - [31/May/2019 14:37:28] "GET /favicon.ico HTTP/1.1" 500 -
INFO _internal.py:88  * Running on http://127.0.0.1:5000/ (Press CTRL+C to quit)
INFO _internal.py:88 127.0.0.1 - - [31/May/2019 14:38:36] "GET /index HTTP/1.1" 404 -
INFO _internal.py:88 127.0.0.1 - - [31/May/2019 14:38:36] "GET /favicon.ico HTTP/1.1" 200 -
INFO _internal.py:88 127.0.0.1 - - [31/May/2019 14:38:41] "GET /index HTTP/1.1" 404 -
INFO _internal.py:88  * Running on http://127.0.0.1:5000/ (Press CTRL+C to quit)
INFO _internal.py:88 127.0.0.1 - - [31/May/2019 14:39:20] "GET / HTTP/1.1" 200 -
INFO _internal.py:88 127.0.0.1 - - [31/May/2019 14:39:20] "GET /static/plugins/bootstrap/css/bootstrap.min.css HTTP/1.1" 304 -
INFO _internal.py:88 127.0.0.1 - - [31/May/2019 14:39:20] "GET /static/plugins/font-awesome/css/font-awesome.min.css HTTP/1.1" 304 -
INFO _internal.py:88 127.0.0.1 - - [31/May/2019 14:39:20] "GET /static/css/reset.css HTTP/1.1" 304 -
INFO _internal.py:88 127.0.0.1 - - [31/May/2019 14:39:20] "GET /static/plugins/swiper/css/swiper.min.css HTTP/1.1" 304 -
INFO _internal.py:88 127.0.0.1 - - [31/May/2019 14:39:20] "GET /static/plugins/bootstrap-datepicker/css/bootstrap-datepicker.min.css HTTP/1.1" 304 -
INFO _internal.py:88 127.0.0.1 - - [31/May/2019 14:39:20] "GET /static/css/ihome/main.css HTTP/1.1" 304 -
INFO _internal.py:88 127.0.0.1 - - [31/May/2019 14:39:20] "GET /static/css/ihome/index.css HTTP/1.1" 304 -
INFO _internal.py:88 127.0.0.1 - - [31/May/2019 14:39:20] "GET /static/images/logo@128x59.png HTTP/1.1" 304 -
INFO _internal.py:88 127.0.0.1 - - [31/May/2019 14:39:20] "GET /static/images/home01.jpg HTTP/1.1" 304 -
INFO _internal.py:88 127.0.0.1 - - [31/May/2019 14:39:20] "GET /static/plugins/swiper/js/swiper.jquery.min.js HTTP/1.1" 304 -
INFO _internal.py:88 127.0.0.1 - - [31/May/2019 14:39:20] "GET /static/js/jquery.min.js HTTP/1.1" 304 -
INFO _internal.py:88 127.0.0.1 - - [31/May/2019 14:39:20] "GET /static/plugins/bootstrap-datepicker/locales/bootstrap-datepicker.zh-CN.min.js HTTP/1.1" 304 -
INFO _internal.py:88 127.0.0.1 - - [31/May/2019 14:39:20] "GET /static/plugins/bootstrap/js/bootstrap.min.js HTTP/1.1" 304 -
INFO _internal.py:88 127.0.0.1 - - [31/May/2019 14:39:20] "GET /static/plugins/bootstrap-datepicker/js/bootstrap-datepicker.min.js HTTP/1.1" 304 -
INFO _internal.py:88 127.0.0.1 - - [31/May/2019 14:39:20] "GET /static/js/template.js HTTP/1.1" 304 -
INFO _internal.py:88 127.0.0.1 - - [31/May/2019 14:39:20] "GET /static/js/ihome/index.js HTTP/1.1" 304 -
INFO _internal.py:88 127.0.0.1 - - [31/May/2019 14:39:20] "GET /static/images/home02.jpg HTTP/1.1" 304 -
INFO _internal.py:88 127.0.0.1 - - [31/May/2019 14:39:20] "GET /static/images/home03.jpg HTTP/1.1" 304 -
INFO _internal.py:88 127.0.0.1 - - [31/May/2019 14:39:21] "GET /static/plugins/font-awesome/fonts/fontawesome-webfont.woff2?v=4.6.3 HTTP/1.1" 304 -
INFO _internal.py:88 127.0.0.1 - - [31/May/2019 14:39:21] "GET /static/plugins/bootstrap/css/bootstrap.min.css.map HTTP/1.1" 304 -
INFO _internal.py:88 127.0.0.1 - - [31/May/2019 14:39:21] "GET /static/plugins/swiper/js/maps/swiper.jquery.min.js.map HTTP/1.1" 404 -
INFO _internal.py:88 127.0.0.1 - - [31/May/2019 14:45:14] "GET /index.html HTTP/1.1" 200 -
INFO _internal.py:88 127.0.0.1 - - [31/May/2019 14:45:15] "GET /static/plugins/swiper/js/maps/swiper.jquery.min.js.map HTTP/1.1" 404 -
INFO _internal.py:88 127.0.0.1 - - [31/May/2019 14:45:20] "GET /my.html HTTP/1.1" 304 -
INFO _internal.py:88 127.0.0.1 - - [31/May/2019 14:45:20] "GET /static/css/ihome/my.css HTTP/1.1" 304 -
INFO _internal.py:88 127.0.0.1 - - [31/May/2019 14:45:20] "GET /static/js/ihome/my.js HTTP/1.1" 304 -
INFO _internal.py:88  * Running on http://127.0.0.1:5000/ (Press CTRL+C to quit)
INFO _internal.py:88 127.0.0.1 - - [06/Jun/2019 11:29:32] "GET / HTTP/1.1" 200 -
INFO _internal.py:88 127.0.0.1 - - [06/Jun/2019 11:29:32] "GET /static/plugins/bootstrap/css/bootstrap.min.css HTTP/1.1" 304 -
INFO _internal.py:88 127.0.0.1 - - [06/Jun/2019 11:29:32] "GET /static/plugins/font-awesome/css/font-awesome.min.css HTTP/1.1" 304 -
INFO _internal.py:88 127.0.0.1 - - [06/Jun/2019 11:29:32] "GET /static/css/reset.css HTTP/1.1" 304 -
INFO _internal.py:88 127.0.0.1 - - [06/Jun/2019 11:29:32] "GET /static/plugins/swiper/css/swiper.min.css HTTP/1.1" 304 -
INFO _internal.py:88 127.0.0.1 - - [06/Jun/2019 11:29:32] "GET /static/plugins/bootstrap-datepicker/css/bootstrap-datepicker.min.css HTTP/1.1" 304 -
INFO _internal.py:88 127.0.0.1 - - [06/Jun/2019 11:29:32] "GET /static/css/ihome/main.css HTTP/1.1" 304 -
INFO _internal.py:88 127.0.0.1 - - [06/Jun/2019 11:29:32] "GET /static/css/ihome/index.css HTTP/1.1" 304 -
INFO _internal.py:88 127.0.0.1 - - [06/Jun/2019 11:29:32] "GET /static/images/logo@128x59.png HTTP/1.1" 304 -
INFO _internal.py:88 127.0.0.1 - - [06/Jun/2019 11:29:32] "GET /static/images/home01.jpg HTTP/1.1" 304 -
INFO _internal.py:88 127.0.0.1 - - [06/Jun/2019 11:29:32] "GET /static/js/jquery.min.js HTTP/1.1" 304 -
INFO _internal.py:88 127.0.0.1 - - [06/Jun/2019 11:29:32] "GET /static/plugins/bootstrap/js/bootstrap.min.js HTTP/1.1" 304 -
INFO _internal.py:88 127.0.0.1 - - [06/Jun/2019 11:29:32] "GET /static/plugins/swiper/js/swiper.jquery.min.js HTTP/1.1" 304 -
INFO _internal.py:88 127.0.0.1 - - [06/Jun/2019 11:29:32] "GET /static/plugins/bootstrap-datepicker/js/bootstrap-datepicker.min.js HTTP/1.1" 304 -
INFO _internal.py:88 127.0.0.1 - - [06/Jun/2019 11:29:32] "GET /static/plugins/bootstrap-datepicker/locales/bootstrap-datepicker.zh-CN.min.js HTTP/1.1" 304 -
INFO _internal.py:88 127.0.0.1 - - [06/Jun/2019 11:29:32] "GET /static/js/template.js HTTP/1.1" 304 -
INFO _internal.py:88 127.0.0.1 - - [06/Jun/2019 11:29:32] "GET /static/js/ihome/index.js HTTP/1.1" 304 -
INFO _internal.py:88 127.0.0.1 - - [06/Jun/2019 11:29:32] "GET /static/images/home02.jpg HTTP/1.1" 304 -
INFO _internal.py:88 127.0.0.1 - - [06/Jun/2019 11:29:32] "GET /static/images/home03.jpg HTTP/1.1" 304 -
INFO _internal.py:88 127.0.0.1 - - [06/Jun/2019 11:29:32] "GET /static/plugins/font-awesome/fonts/fontawesome-webfont.woff2?v=4.6.3 HTTP/1.1" 304 -
INFO _internal.py:88 127.0.0.1 - - [06/Jun/2019 11:29:35] "GET /search.html?aid=&aname=&sd=&ed= HTTP/1.1" 304 -
INFO _internal.py:88 127.0.0.1 - - [06/Jun/2019 11:29:35] "GET /static/css/ihome/search.css HTTP/1.1" 304 -
INFO _internal.py:88 127.0.0.1 - - [06/Jun/2019 11:29:35] "GET /static/js/ihome/search.js HTTP/1.1" 200 -
INFO _internal.py:88 127.0.0.1 - - [06/Jun/2019 11:29:35] "GET /static/images/landlord01.jgp HTTP/1.1" 404 -
INFO _internal.py:88 127.0.0.1 - - [06/Jun/2019 11:29:46] "GET /login.html HTTP/1.1" 200 -
INFO _internal.py:88 127.0.0.1 - - [06/Jun/2019 11:29:46] "GET /static/css/ihome/login.css HTTP/1.1" 200 -
INFO _internal.py:88 127.0.0.1 - - [06/Jun/2019 11:29:46] "GET /static/js/ihome/login.js HTTP/1.1" 200 -
INFO _internal.py:88 127.0.0.1 - - [06/Jun/2019 11:29:50] "GET /register.html HTTP/1.1" 200 -
INFO _internal.py:88 127.0.0.1 - - [06/Jun/2019 11:29:51] "GET /static/css/ihome/register.css HTTP/1.1" 200 -
INFO _internal.py:88 127.0.0.1 - - [06/Jun/2019 11:29:51] "GET /static/js/ihome/register.js HTTP/1.1" 200 -
INFO _internal.py:88  * Running on http://127.0.0.1:5000/ (Press CTRL+C to quit)
INFO _internal.py:88  * Running on http://127.0.0.1:5000/ (Press CTRL+C to quit)
INFO _internal.py:88 127.0.0.1 - - [06/Jun/2019 11:50:10] "GET /register.html HTTP/1.1" 304 -
INFO _internal.py:88 127.0.0.1 - - [06/Jun/2019 11:53:27] "GET /api_1_0/images_codes/123 HTTP/1.1" 404 -
ERROR app.py:1761 Exception on /api/V1.0/images_codes/123 [GET]
Traceback (most recent call last):
  File "D:\Program\Python37\lib\site-packages\flask\app.py", line 2292, in wsgi_app
    response = self.full_dispatch_request()
  File "D:\Program\Python37\lib\site-packages\flask\app.py", line 1815, in full_dispatch_request
    rv = self.handle_user_exception(e)
  File "D:\Program\Python37\lib\site-packages\flask\app.py", line 1718, in handle_user_exception
    reraise(exc_type, exc_value, tb)
  File "D:\Program\Python37\lib\site-packages\flask\_compat.py", line 35, in reraise
    raise value
  File "D:\Program\Python37\lib\site-packages\flask\app.py", line 1813, in full_dispatch_request
    rv = self.dispatch_request()
  File "D:\Program\Python37\lib\site-packages\flask\app.py", line 1799, in dispatch_request
    return self.view_functions[rule.endpoint](**req.view_args)
  File "C:\Users\top\PycharmProjects\Ihome\ihome\api_1_0\verifyCode.py", line 14, in get_image_code
    name, text, image_data = captcha.generate_captcha()
  File "C:\Users\top\PycharmProjects\Ihome\ihome\utils\captcha\captcha.py", line 217, in generate_captcha
    self.initialize()
  File "C:\Users\top\PycharmProjects\Ihome\ihome\utils\captcha\captcha.py", line 71, in initialize
    self._text = text if text else random.sample(string.uppercase + string.uppercase + '3456789', 4)
AttributeError: module 'string' has no attribute 'uppercase'
INFO _internal.py:88 127.0.0.1 - - [06/Jun/2019 11:53:43] "GET /api/V1.0/images_codes/123 HTTP/1.1" 500 -
ERROR app.py:1761 Exception on /api/V1.0/images_codes/123 [GET]
Traceback (most recent call last):
  File "D:\Program\Python37\lib\site-packages\flask\app.py", line 2292, in wsgi_app
    response = self.full_dispatch_request()
  File "D:\Program\Python37\lib\site-packages\flask\app.py", line 1815, in full_dispatch_request
    rv = self.handle_user_exception(e)
  File "D:\Program\Python37\lib\site-packages\flask\app.py", line 1718, in handle_user_exception
    reraise(exc_type, exc_value, tb)
  File "D:\Program\Python37\lib\site-packages\flask\_compat.py", line 35, in reraise
    raise value
  File "D:\Program\Python37\lib\site-packages\flask\app.py", line 1813, in full_dispatch_request
    rv = self.dispatch_request()
  File "D:\Program\Python37\lib\site-packages\flask\app.py", line 1799, in dispatch_request
    return self.view_functions[rule.endpoint](**req.view_args)
  File "C:\Users\top\PycharmProjects\Ihome\ihome\api_1_0\verifyCode.py", line 14, in get_image_code
    name, text, image_data = captcha.generate_captcha()
  File "C:\Users\top\PycharmProjects\Ihome\ihome\utils\captcha\captcha.py", line 217, in generate_captcha
    self.initialize()
  File "C:\Users\top\PycharmProjects\Ihome\ihome\utils\captcha\captcha.py", line 71, in initialize
    self._text = text if text else random.sample(string.uppercase + string.uppercase + '3456789', 4)
AttributeError: module 'string' has no attribute 'uppercase'
INFO _internal.py:88 127.0.0.1 - - [06/Jun/2019 11:53:46] "GET /api/V1.0/images_codes/123 HTTP/1.1" 500 -
ERROR app.py:1761 Exception on /api/V1.0/images_codes/abc [GET]
Traceback (most recent call last):
  File "D:\Program\Python37\lib\site-packages\flask\app.py", line 2292, in wsgi_app
    response = self.full_dispatch_request()
  File "D:\Program\Python37\lib\site-packages\flask\app.py", line 1815, in full_dispatch_request
    rv = self.handle_user_exception(e)
  File "D:\Program\Python37\lib\site-packages\flask\app.py", line 1718, in handle_user_exception
    reraise(exc_type, exc_value, tb)
  File "D:\Program\Python37\lib\site-packages\flask\_compat.py", line 35, in reraise
    raise value
  File "D:\Program\Python37\lib\site-packages\flask\app.py", line 1813, in full_dispatch_request
    rv = self.dispatch_request()
  File "D:\Program\Python37\lib\site-packages\flask\app.py", line 1799, in dispatch_request
    return self.view_functions[rule.endpoint](**req.view_args)
  File "C:\Users\top\PycharmProjects\Ihome\ihome\api_1_0\verifyCode.py", line 14, in get_image_code
    name, text, image_data = captcha.generate_captcha()
  File "C:\Users\top\PycharmProjects\Ihome\ihome\utils\captcha\captcha.py", line 217, in generate_captcha
    self.initialize()
  File "C:\Users\top\PycharmProjects\Ihome\ihome\utils\captcha\captcha.py", line 71, in initialize
    self._text = text if text else random.sample(string.uppercase + string.uppercase + '3456789', 4)
AttributeError: module 'string' has no attribute 'uppercase'
INFO _internal.py:88 127.0.0.1 - - [06/Jun/2019 11:56:48] "GET /api/V1.0/images_codes/abc HTTP/1.1" 500 -
ERROR app.py:1761 Exception on /api/V1.0/images_codes/abc [GET]
Traceback (most recent call last):
  File "D:\Program\Python37\lib\site-packages\flask\app.py", line 2292, in wsgi_app
    response = self.full_dispatch_request()
  File "D:\Program\Python37\lib\site-packages\flask\app.py", line 1815, in full_dispatch_request
    rv = self.handle_user_exception(e)
  File "D:\Program\Python37\lib\site-packages\flask\app.py", line 1718, in handle_user_exception
    reraise(exc_type, exc_value, tb)
  File "D:\Program\Python37\lib\site-packages\flask\_compat.py", line 35, in reraise
    raise value
  File "D:\Program\Python37\lib\site-packages\flask\app.py", line 1813, in full_dispatch_request
    rv = self.dispatch_request()
  File "D:\Program\Python37\lib\site-packages\flask\app.py", line 1799, in dispatch_request
    return self.view_functions[rule.endpoint](**req.view_args)
  File "C:\Users\top\PycharmProjects\Ihome\ihome\api_1_0\verifyCode.py", line 14, in get_image_code
    name, text, image_data = captcha.generate_captcha()
  File "C:\Users\top\PycharmProjects\Ihome\ihome\utils\captcha\captcha.py", line 217, in generate_captcha
    self.initialize()
  File "C:\Users\top\PycharmProjects\Ihome\ihome\utils\captcha\captcha.py", line 71, in initialize
    self._text = text if text else random.sample(string.uppercase + string.uppercase + '3456789', 4)
AttributeError: module 'string' has no attribute 'uppercase'
INFO _internal.py:88 127.0.0.1 - - [06/Jun/2019 11:57:37] "GET /api/V1.0/images_codes/abc HTTP/1.1" 500 -
INFO _internal.py:88  * Running on http://127.0.0.1:5000/ (Press CTRL+C to quit)
ERROR app.py:1761 Exception on /api/V1.0/images_codes/abc [GET]
Traceback (most recent call last):
  File "D:\Program\Python37\lib\site-packages\flask\app.py", line 2292, in wsgi_app
    response = self.full_dispatch_request()
  File "D:\Program\Python37\lib\site-packages\flask\app.py", line 1815, in full_dispatch_request
    rv = self.handle_user_exception(e)
  File "D:\Program\Python37\lib\site-packages\flask\app.py", line 1718, in handle_user_exception
    reraise(exc_type, exc_value, tb)
  File "D:\Program\Python37\lib\site-packages\flask\_compat.py", line 35, in reraise
    raise value
  File "D:\Program\Python37\lib\site-packages\flask\app.py", line 1813, in full_dispatch_request
    rv = self.dispatch_request()
  File "D:\Program\Python37\lib\site-packages\flask\app.py", line 1799, in dispatch_request
    return self.view_functions[rule.endpoint](**req.view_args)
  File "C:\Users\top\PycharmProjects\Ihome\ihome\api_1_0\verifyCode.py", line 14, in get_image_code
    name, text, image_data = captcha.generate_captcha()
  File "C:\Users\top\PycharmProjects\Ihome\ihome\utils\captcha\captcha.py", line 218, in generate_captcha
    return self.captcha("")
  File "C:\Users\top\PycharmProjects\Ihome\ihome\utils\captcha\captcha.py", line 208, in captcha
    name = "".join(random.sample(string.lowercase + string.uppercase + '3456789', 24))
AttributeError: module 'string' has no attribute 'lowercase'
INFO _internal.py:88 127.0.0.1 - - [06/Jun/2019 11:58:47] "GET /api/V1.0/images_codes/abc HTTP/1.1" 500 -
ERROR app.py:1761 Exception on /api/V1.0/images_codes/abc [GET]
Traceback (most recent call last):
  File "D:\Program\Python37\lib\site-packages\flask\app.py", line 2292, in wsgi_app
    response = self.full_dispatch_request()
  File "D:\Program\Python37\lib\site-packages\flask\app.py", line 1815, in full_dispatch_request
    rv = self.handle_user_exception(e)
  File "D:\Program\Python37\lib\site-packages\flask\app.py", line 1718, in handle_user_exception
    reraise(exc_type, exc_value, tb)
  File "D:\Program\Python37\lib\site-packages\flask\_compat.py", line 35, in reraise
    raise value
  File "D:\Program\Python37\lib\site-packages\flask\app.py", line 1813, in full_dispatch_request
    rv = self.dispatch_request()
  File "D:\Program\Python37\lib\site-packages\flask\app.py", line 1799, in dispatch_request
    return self.view_functions[rule.endpoint](**req.view_args)
  File "C:\Users\top\PycharmProjects\Ihome\ihome\api_1_0\verifyCode.py", line 14, in get_image_code
    name, text, image_data = captcha.generate_captcha()
  File "C:\Users\top\PycharmProjects\Ihome\ihome\utils\captcha\captcha.py", line 218, in generate_captcha
    return self.captcha("")
  File "C:\Users\top\PycharmProjects\Ihome\ihome\utils\captcha\captcha.py", line 208, in captcha
    name = "".join(random.sample(string.lowercase + string.uppercase + '3456789', 24))
AttributeError: module 'string' has no attribute 'lowercase'
INFO _internal.py:88 127.0.0.1 - - [06/Jun/2019 11:58:49] "GET /api/V1.0/images_codes/abc HTTP/1.1" 500 -
INFO _internal.py:88  * Running on http://127.0.0.1:5000/ (Press CTRL+C to quit)
ERROR app.py:1761 Exception on /api/V1.0/images_codes/abc [GET]
Traceback (most recent call last):
  File "D:\Program\Python37\lib\site-packages\PIL\ImageFile.py", line 488, in _save
    fh = fp.fileno()
io.UnsupportedOperation: fileno

During handling of the above exception, another exception occurred:

Traceback (most recent call last):
  File "D:\Program\Python37\lib\site-packages\flask\app.py", line 2292, in wsgi_app
    response = self.full_dispatch_request()
  File "D:\Program\Python37\lib\site-packages\flask\app.py", line 1815, in full_dispatch_request
    rv = self.handle_user_exception(e)
  File "D:\Program\Python37\lib\site-packages\flask\app.py", line 1718, in handle_user_exception
    reraise(exc_type, exc_value, tb)
  File "D:\Program\Python37\lib\site-packages\flask\_compat.py", line 35, in reraise
    raise value
  File "D:\Program\Python37\lib\site-packages\flask\app.py", line 1813, in full_dispatch_request
    rv = self.dispatch_request()
  File "D:\Program\Python37\lib\site-packages\flask\app.py", line 1799, in dispatch_request
    return self.view_functions[rule.endpoint](**req.view_args)
  File "C:\Users\top\PycharmProjects\Ihome\ihome\api_1_0\verifyCode.py", line 14, in get_image_code
    name, text, image_data = captcha.generate_captcha()
  File "C:\Users\top\PycharmProjects\Ihome\ihome\utils\captcha\captcha.py", line 218, in generate_captcha
    return self.captcha("")
  File "C:\Users\top\PycharmProjects\Ihome\ihome\utils\captcha\captcha.py", line 211, in captcha
    image.save(out, format=fmt)
  File "D:\Program\Python37\lib\site-packages\PIL\Image.py", line 2007, in save
    save_handler(self, fp, filename)
  File "D:\Program\Python37\lib\site-packages\PIL\JpegImagePlugin.py", line 765, in _save
    ImageFile._save(im, fp, [("jpeg", (0, 0)+im.size, 0, rawmode)], bufsize)
  File "D:\Program\Python37\lib\site-packages\PIL\ImageFile.py", line 503, in _save
    fp.write(d)
TypeError: string argument expected, got 'bytes'
INFO _internal.py:88 127.0.0.1 - - [06/Jun/2019 12:00:16] "GET /api/V1.0/images_codes/abc HTTP/1.1" 500 -
ERROR app.py:1761 Exception on /api/V1.0/images_codes/abc [GET]
Traceback (most recent call last):
  File "D:\Program\Python37\lib\site-packages\PIL\ImageFile.py", line 488, in _save
    fh = fp.fileno()
io.UnsupportedOperation: fileno

During handling of the above exception, another exception occurred:

Traceback (most recent call last):
  File "D:\Program\Python37\lib\site-packages\flask\app.py", line 2292, in wsgi_app
    response = self.full_dispatch_request()
  File "D:\Program\Python37\lib\site-packages\flask\app.py", line 1815, in full_dispatch_request
    rv = self.handle_user_exception(e)
  File "D:\Program\Python37\lib\site-packages\flask\app.py", line 1718, in handle_user_exception
    reraise(exc_type, exc_value, tb)
  File "D:\Program\Python37\lib\site-packages\flask\_compat.py", line 35, in reraise
    raise value
  File "D:\Program\Python37\lib\site-packages\flask\app.py", line 1813, in full_dispatch_request
    rv = self.dispatch_request()
  File "D:\Program\Python37\lib\site-packages\flask\app.py", line 1799, in dispatch_request
    return self.view_functions[rule.endpoint](**req.view_args)
  File "C:\Users\top\PycharmProjects\Ihome\ihome\api_1_0\verifyCode.py", line 14, in get_image_code
    name, text, image_data = captcha.generate_captcha()
  File "C:\Users\top\PycharmProjects\Ihome\ihome\utils\captcha\captcha.py", line 218, in generate_captcha
    return self.captcha("")
  File "C:\Users\top\PycharmProjects\Ihome\ihome\utils\captcha\captcha.py", line 211, in captcha
    image.save(out, format=fmt)
  File "D:\Program\Python37\lib\site-packages\PIL\Image.py", line 2007, in save
    save_handler(self, fp, filename)
  File "D:\Program\Python37\lib\site-packages\PIL\JpegImagePlugin.py", line 765, in _save
    ImageFile._save(im, fp, [("jpeg", (0, 0)+im.size, 0, rawmode)], bufsize)
  File "D:\Program\Python37\lib\site-packages\PIL\ImageFile.py", line 503, in _save
    fp.write(d)
TypeError: string argument expected, got 'bytes'
INFO _internal.py:88 127.0.0.1 - - [06/Jun/2019 12:00:19] "GET /api/V1.0/images_codes/abc HTTP/1.1" 500 -
ERROR app.py:1761 Exception on /api/V1.0/images_codes/abc [GET]
Traceback (most recent call last):
  File "D:\Program\Python37\lib\site-packages\PIL\ImageFile.py", line 488, in _save
    fh = fp.fileno()
io.UnsupportedOperation: fileno

During handling of the above exception, another exception occurred:

Traceback (most recent call last):
  File "D:\Program\Python37\lib\site-packages\flask\app.py", line 2292, in wsgi_app
    response = self.full_dispatch_request()
  File "D:\Program\Python37\lib\site-packages\flask\app.py", line 1815, in full_dispatch_request
    rv = self.handle_user_exception(e)
  File "D:\Program\Python37\lib\site-packages\flask\app.py", line 1718, in handle_user_exception
    reraise(exc_type, exc_value, tb)
  File "D:\Program\Python37\lib\site-packages\flask\_compat.py", line 35, in reraise
    raise value
  File "D:\Program\Python37\lib\site-packages\flask\app.py", line 1813, in full_dispatch_request
    rv = self.dispatch_request()
  File "D:\Program\Python37\lib\site-packages\flask\app.py", line 1799, in dispatch_request
    return self.view_functions[rule.endpoint](**req.view_args)
  File "C:\Users\top\PycharmProjects\Ihome\ihome\api_1_0\verifyCode.py", line 14, in get_image_code
    name, text, image_data = captcha.generate_captcha()
  File "C:\Users\top\PycharmProjects\Ihome\ihome\utils\captcha\captcha.py", line 218, in generate_captcha
    return self.captcha("")
  File "C:\Users\top\PycharmProjects\Ihome\ihome\utils\captcha\captcha.py", line 211, in captcha
    image.save(out, format=fmt)
  File "D:\Program\Python37\lib\site-packages\PIL\Image.py", line 2007, in save
    save_handler(self, fp, filename)
  File "D:\Program\Python37\lib\site-packages\PIL\JpegImagePlugin.py", line 765, in _save
    ImageFile._save(im, fp, [("jpeg", (0, 0)+im.size, 0, rawmode)], bufsize)
  File "D:\Program\Python37\lib\site-packages\PIL\ImageFile.py", line 503, in _save
    fp.write(d)
TypeError: string argument expected, got 'bytes'
INFO _internal.py:88 127.0.0.1 - - [06/Jun/2019 12:00:22] "GET /api/V1.0/images_codes/abc HTTP/1.1" 500 -
ERROR app.py:1761 Exception on /api/V1.0/images_codes/abc [GET]
Traceback (most recent call last):
  File "D:\Program\Python37\lib\site-packages\PIL\ImageFile.py", line 488, in _save
    fh = fp.fileno()
io.UnsupportedOperation: fileno

During handling of the above exception, another exception occurred:

Traceback (most recent call last):
  File "D:\Program\Python37\lib\site-packages\flask\app.py", line 2292, in wsgi_app
    response = self.full_dispatch_request()
  File "D:\Program\Python37\lib\site-packages\flask\app.py", line 1815, in full_dispatch_request
    rv = self.handle_user_exception(e)
  File "D:\Program\Python37\lib\site-packages\flask\app.py", line 1718, in handle_user_exception
    reraise(exc_type, exc_value, tb)
  File "D:\Program\Python37\lib\site-packages\flask\_compat.py", line 35, in reraise
    raise value
  File "D:\Program\Python37\lib\site-packages\flask\app.py", line 1813, in full_dispatch_request
    rv = self.dispatch_request()
  File "D:\Program\Python37\lib\site-packages\flask\app.py", line 1799, in dispatch_request
    return self.view_functions[rule.endpoint](**req.view_args)
  File "C:\Users\top\PycharmProjects\Ihome\ihome\api_1_0\verifyCode.py", line 14, in get_image_code
    name, text, image_data = captcha.generate_captcha()
  File "C:\Users\top\PycharmProjects\Ihome\ihome\utils\captcha\captcha.py", line 218, in generate_captcha
    return self.captcha("")
  File "C:\Users\top\PycharmProjects\Ihome\ihome\utils\captcha\captcha.py", line 211, in captcha
    image.save(str(out), format=fmt)
  File "D:\Program\Python37\lib\site-packages\PIL\Image.py", line 2007, in save
    save_handler(self, fp, filename)
  File "D:\Program\Python37\lib\site-packages\PIL\JpegImagePlugin.py", line 765, in _save
    ImageFile._save(im, fp, [("jpeg", (0, 0)+im.size, 0, rawmode)], bufsize)
  File "D:\Program\Python37\lib\site-packages\PIL\ImageFile.py", line 503, in _save
    fp.write(d)
TypeError: string argument expected, got 'bytes'
INFO _internal.py:88 127.0.0.1 - - [06/Jun/2019 12:02:55] "GET /api/V1.0/images_codes/abc HTTP/1.1" 500 -
ERROR app.py:1761 Exception on /api/V1.0/images_codes/abc [GET]
Traceback (most recent call last):
  File "D:\Program\Python37\lib\site-packages\PIL\ImageFile.py", line 488, in _save
    fh = fp.fileno()
io.UnsupportedOperation: fileno

During handling of the above exception, another exception occurred:

Traceback (most recent call last):
  File "D:\Program\Python37\lib\site-packages\flask\app.py", line 2292, in wsgi_app
    response = self.full_dispatch_request()
  File "D:\Program\Python37\lib\site-packages\flask\app.py", line 1815, in full_dispatch_request
    rv = self.handle_user_exception(e)
  File "D:\Program\Python37\lib\site-packages\flask\app.py", line 1718, in handle_user_exception
    reraise(exc_type, exc_value, tb)
  File "D:\Program\Python37\lib\site-packages\flask\_compat.py", line 35, in reraise
    raise value
  File "D:\Program\Python37\lib\site-packages\flask\app.py", line 1813, in full_dispatch_request
    rv = self.dispatch_request()
  File "D:\Program\Python37\lib\site-packages\flask\app.py", line 1799, in dispatch_request
    return self.view_functions[rule.endpoint](**req.view_args)
  File "C:\Users\top\PycharmProjects\Ihome\ihome\api_1_0\verifyCode.py", line 14, in get_image_code
    name, text, image_data = captcha.generate_captcha()
  File "C:\Users\top\PycharmProjects\Ihome\ihome\utils\captcha\captcha.py", line 218, in generate_captcha
    return self.captcha("")
  File "C:\Users\top\PycharmProjects\Ihome\ihome\utils\captcha\captcha.py", line 211, in captcha
    image.save(str(out), format=fmt)
  File "D:\Program\Python37\lib\site-packages\PIL\Image.py", line 2007, in save
    save_handler(self, fp, filename)
  File "D:\Program\Python37\lib\site-packages\PIL\JpegImagePlugin.py", line 765, in _save
    ImageFile._save(im, fp, [("jpeg", (0, 0)+im.size, 0, rawmode)], bufsize)
  File "D:\Program\Python37\lib\site-packages\PIL\ImageFile.py", line 503, in _save
    fp.write(d)
TypeError: string argument expected, got 'bytes'
INFO _internal.py:88 127.0.0.1 - - [06/Jun/2019 12:02:58] "GET /api/V1.0/images_codes/abc HTTP/1.1" 500 -
INFO _internal.py:88 127.0.0.1 - - [06/Jun/2019 12:02:58] "GET /favicon.ico HTTP/1.1" 200 -
ERROR app.py:1761 Exception on /api/V1.0/images_codes/abc [GET]
Traceback (most recent call last):
  File "D:\Program\Python37\lib\site-packages\PIL\ImageFile.py", line 488, in _save
    fh = fp.fileno()
io.UnsupportedOperation: fileno

During handling of the above exception, another exception occurred:

Traceback (most recent call last):
  File "D:\Program\Python37\lib\site-packages\flask\app.py", line 2292, in wsgi_app
    response = self.full_dispatch_request()
  File "D:\Program\Python37\lib\site-packages\flask\app.py", line 1815, in full_dispatch_request
    rv = self.handle_user_exception(e)
  File "D:\Program\Python37\lib\site-packages\flask\app.py", line 1718, in handle_user_exception
    reraise(exc_type, exc_value, tb)
  File "D:\Program\Python37\lib\site-packages\flask\_compat.py", line 35, in reraise
    raise value
  File "D:\Program\Python37\lib\site-packages\flask\app.py", line 1813, in full_dispatch_request
    rv = self.dispatch_request()
  File "D:\Program\Python37\lib\site-packages\flask\app.py", line 1799, in dispatch_request
    return self.view_functions[rule.endpoint](**req.view_args)
  File "C:\Users\top\PycharmProjects\Ihome\ihome\api_1_0\verifyCode.py", line 14, in get_image_code
    name, text, image_data = captcha.generate_captcha()
  File "C:\Users\top\PycharmProjects\Ihome\ihome\utils\captcha\captcha.py", line 218, in generate_captcha
    return self.captcha("")
  File "C:\Users\top\PycharmProjects\Ihome\ihome\utils\captcha\captcha.py", line 211, in captcha
    image.save(str(out), format=fmt)
  File "D:\Program\Python37\lib\site-packages\PIL\Image.py", line 2007, in save
    save_handler(self, fp, filename)
  File "D:\Program\Python37\lib\site-packages\PIL\JpegImagePlugin.py", line 765, in _save
    ImageFile._save(im, fp, [("jpeg", (0, 0)+im.size, 0, rawmode)], bufsize)
  File "D:\Program\Python37\lib\site-packages\PIL\ImageFile.py", line 503, in _save
    fp.write(d)
TypeError: string argument expected, got 'bytes'
INFO _internal.py:88 127.0.0.1 - - [06/Jun/2019 12:02:58] "GET /api/V1.0/images_codes/abc HTTP/1.1" 500 -
INFO _internal.py:88 127.0.0.1 - - [06/Jun/2019 12:02:59] "GET /favicon.ico HTTP/1.1" 200 -
INFO _internal.py:88  * Running on http://127.0.0.1:5000/ (Press CTRL+C to quit)
ERROR app.py:1761 Exception on /api/V1.0/images_codes/abc [GET]
Traceback (most recent call last):
  File "D:\Program\Python37\lib\site-packages\flask\app.py", line 2292, in wsgi_app
    response = self.full_dispatch_request()
  File "D:\Program\Python37\lib\site-packages\flask\app.py", line 1815, in full_dispatch_request
    rv = self.handle_user_exception(e)
  File "D:\Program\Python37\lib\site-packages\flask\app.py", line 1718, in handle_user_exception
    reraise(exc_type, exc_value, tb)
  File "D:\Program\Python37\lib\site-packages\flask\_compat.py", line 35, in reraise
    raise value
  File "D:\Program\Python37\lib\site-packages\flask\app.py", line 1813, in full_dispatch_request
    rv = self.dispatch_request()
  File "D:\Program\Python37\lib\site-packages\flask\app.py", line 1799, in dispatch_request
    return self.view_functions[rule.endpoint](**req.view_args)
  File "C:\Users\top\PycharmProjects\Ihome\ihome\api_1_0\verifyCode.py", line 14, in get_image_code
    name, text, image_data = captcha.generate_captcha()
  File "C:\Users\top\PycharmProjects\Ihome\ihome\utils\captcha\captcha.py", line 218, in generate_captcha
    return self.captcha("")
  File "C:\Users\top\PycharmProjects\Ihome\ihome\utils\captcha\captcha.py", line 211, in captcha
    image.save(str(out), format=fmt)
  File "D:\Program\Python37\lib\site-packages\PIL\Image.py", line 2004, in save
    fp = builtins.open(filename, "w+b")
OSError: [Errno 22] Invalid argument: '<_io.StringIO object at 0x000001C982ABDE58>'
INFO _internal.py:88 127.0.0.1 - - [06/Jun/2019 12:03:12] "GET /api/V1.0/images_codes/abc HTTP/1.1" 500 -
INFO _internal.py:88 127.0.0.1 - - [06/Jun/2019 12:03:13] "GET /favicon.ico HTTP/1.1" 200 -
ERROR app.py:1761 Exception on /api/V1.0/images_codes/abc [GET]
Traceback (most recent call last):
  File "D:\Program\Python37\lib\site-packages\flask\app.py", line 2292, in wsgi_app
    response = self.full_dispatch_request()
  File "D:\Program\Python37\lib\site-packages\flask\app.py", line 1815, in full_dispatch_request
    rv = self.handle_user_exception(e)
  File "D:\Program\Python37\lib\site-packages\flask\app.py", line 1718, in handle_user_exception
    reraise(exc_type, exc_value, tb)
  File "D:\Program\Python37\lib\site-packages\flask\_compat.py", line 35, in reraise
    raise value
  File "D:\Program\Python37\lib\site-packages\flask\app.py", line 1813, in full_dispatch_request
    rv = self.dispatch_request()
  File "D:\Program\Python37\lib\site-packages\flask\app.py", line 1799, in dispatch_request
    return self.view_functions[rule.endpoint](**req.view_args)
  File "C:\Users\top\PycharmProjects\Ihome\ihome\api_1_0\verifyCode.py", line 14, in get_image_code
    name, text, image_data = captcha.generate_captcha()
  File "C:\Users\top\PycharmProjects\Ihome\ihome\utils\captcha\captcha.py", line 218, in generate_captcha
    return self.captcha("")
  File "C:\Users\top\PycharmProjects\Ihome\ihome\utils\captcha\captcha.py", line 211, in captcha
    image.save(str(out), format=fmt)
  File "D:\Program\Python37\lib\site-packages\PIL\Image.py", line 2004, in save
    fp = builtins.open(filename, "w+b")
OSError: [Errno 22] Invalid argument: '<_io.StringIO object at 0x000001C982AB79D8>'
INFO _internal.py:88 127.0.0.1 - - [06/Jun/2019 12:03:13] "GET /api/V1.0/images_codes/abc HTTP/1.1" 500 -
INFO _internal.py:88 127.0.0.1 - - [06/Jun/2019 12:03:13] "GET /favicon.ico HTTP/1.1" 200 -
ERROR app.py:1761 Exception on /api/V1.0/images_codes/abc [GET]
Traceback (most recent call last):
  File "D:\Program\Python37\lib\site-packages\flask\app.py", line 2292, in wsgi_app
    response = self.full_dispatch_request()
  File "D:\Program\Python37\lib\site-packages\flask\app.py", line 1815, in full_dispatch_request
    rv = self.handle_user_exception(e)
  File "D:\Program\Python37\lib\site-packages\flask\app.py", line 1718, in handle_user_exception
    reraise(exc_type, exc_value, tb)
  File "D:\Program\Python37\lib\site-packages\flask\_compat.py", line 35, in reraise
    raise value
  File "D:\Program\Python37\lib\site-packages\flask\app.py", line 1813, in full_dispatch_request
    rv = self.dispatch_request()
  File "D:\Program\Python37\lib\site-packages\flask\app.py", line 1799, in dispatch_request
    return self.view_functions[rule.endpoint](**req.view_args)
  File "C:\Users\top\PycharmProjects\Ihome\ihome\api_1_0\verifyCode.py", line 14, in get_image_code
    name, text, image_data = captcha.generate_captcha()
  File "C:\Users\top\PycharmProjects\Ihome\ihome\utils\captcha\captcha.py", line 218, in generate_captcha
    return self.captcha("")
  File "C:\Users\top\PycharmProjects\Ihome\ihome\utils\captcha\captcha.py", line 211, in captcha
    image.save(str(out), format=fmt)
  File "D:\Program\Python37\lib\site-packages\PIL\Image.py", line 2004, in save
    fp = builtins.open(filename, "w+b")
OSError: [Errno 22] Invalid argument: '<_io.StringIO object at 0x000001C982ABDE58>'
INFO _internal.py:88 127.0.0.1 - - [06/Jun/2019 12:03:14] "GET /api/V1.0/images_codes/abc HTTP/1.1" 500 -
INFO _internal.py:88 127.0.0.1 - - [06/Jun/2019 12:03:14] "GET /favicon.ico HTTP/1.1" 200 -
INFO _internal.py:88  * Running on http://127.0.0.1:5000/ (Press CTRL+C to quit)
INFO _internal.py:88 127.0.0.1 - - [06/Jun/2019 13:43:48] "GET /api/V1.0/images_codes/abc HTTP/1.1" 200 -
INFO _internal.py:88 127.0.0.1 - - [06/Jun/2019 13:43:54] "GET /api/V1.0/images_codes/abc HTTP/1.1" 200 -
INFO _internal.py:88 127.0.0.1 - - [06/Jun/2019 13:43:56] "GET /api/V1.0/images_codes/abc HTTP/1.1" 200 -
INFO _internal.py:88 127.0.0.1 - - [06/Jun/2019 13:50:47] "GET /api/V1.0/images_codes/abc HTTP/1.1" 200 -
INFO _internal.py:88  * Running on http://127.0.0.1:5000/ (Press CTRL+C to quit)
INFO _internal.py:88 127.0.0.1 - - [06/Jun/2019 14:46:31] "GET /api/V1.0/images_codes/123 HTTP/1.1" 200 -
INFO _internal.py:88 127.0.0.1 - - [06/Jun/2019 14:46:31] "GET /favicon.ico HTTP/1.1" 200 -
INFO _internal.py:88 127.0.0.1 - - [06/Jun/2019 14:46:32] "GET /api/V1.0/images_codes/123 HTTP/1.1" 200 -
INFO _internal.py:88 127.0.0.1 - - [06/Jun/2019 14:46:32] "GET /favicon.ico HTTP/1.1" 200 -
INFO _internal.py:88 127.0.0.1 - - [06/Jun/2019 14:46:32] "GET /api/V1.0/images_codes/123 HTTP/1.1" 200 -
INFO _internal.py:88 127.0.0.1 - - [06/Jun/2019 14:46:32] "GET /favicon.ico HTTP/1.1" 200 -
INFO _internal.py:88 127.0.0.1 - - [06/Jun/2019 14:46:33] "GET /api/V1.0/images_codes/123 HTTP/1.1" 200 -
INFO _internal.py:88 127.0.0.1 - - [06/Jun/2019 14:46:33] "GET /favicon.ico HTTP/1.1" 200 -
INFO _internal.py:88 127.0.0.1 - - [06/Jun/2019 14:46:38] "GET /register.html HTTP/1.1" 200 -
INFO _internal.py:88 127.0.0.1 - - [06/Jun/2019 14:46:40] "GET /register.html HTTP/1.1" 304 -
INFO _internal.py:88 127.0.0.1 - - [06/Jun/2019 14:46:47] "GET /static/plugins/bootstrap/css/bootstrap.min.css.map HTTP/1.1" 304 -
INFO _internal.py:88 127.0.0.1 - - [06/Jun/2019 14:47:33] "GET /register.html HTTP/1.1" 200 -
INFO _internal.py:88 127.0.0.1 - - [06/Jun/2019 14:47:33] "GET /static/plugins/bootstrap/css/bootstrap.min.css HTTP/1.1" 200 -
INFO _internal.py:88 127.0.0.1 - - [06/Jun/2019 14:47:33] "GET /static/plugins/font-awesome/css/font-awesome.min.css HTTP/1.1" 200 -
INFO _internal.py:88 127.0.0.1 - - [06/Jun/2019 14:47:33] "GET /static/css/reset.css HTTP/1.1" 200 -
INFO _internal.py:88 127.0.0.1 - - [06/Jun/2019 14:47:33] "GET /static/css/ihome/main.css HTTP/1.1" 200 -
INFO _internal.py:88 127.0.0.1 - - [06/Jun/2019 14:47:33] "GET /static/css/ihome/register.css HTTP/1.1" 200 -
INFO _internal.py:88 127.0.0.1 - - [06/Jun/2019 14:47:33] "GET /static/images/logo@128x59.png HTTP/1.1" 200 -
INFO _internal.py:88 127.0.0.1 - - [06/Jun/2019 14:47:33] "GET /static/js/jquery.min.js HTTP/1.1" 200 -
INFO _internal.py:88 127.0.0.1 - - [06/Jun/2019 14:47:33] "GET /static/plugins/bootstrap/js/bootstrap.min.js HTTP/1.1" 200 -
INFO _internal.py:88 127.0.0.1 - - [06/Jun/2019 14:47:33] "GET /static/js/ihome/register.js HTTP/1.1" 200 -
INFO _internal.py:88 127.0.0.1 - - [06/Jun/2019 14:47:33] "GET /static/plugins/bootstrap/css/bootstrap.min.css.map HTTP/1.1" 200 -
INFO _internal.py:88 127.0.0.1 - - [06/Jun/2019 14:47:33] "GET /static/plugins/font-awesome/fonts/fontawesome-webfont.woff2?v=4.6.3 HTTP/1.1" 200 -
INFO _internal.py:88 127.0.0.1 - - [06/Jun/2019 14:47:33] "GET /api/V1.0/images_codes/4dd0a03c-7f6d-4f3b-84ba-ea7c7f03eb3d HTTP/1.1" 200 -
INFO _internal.py:88 127.0.0.1 - - [06/Jun/2019 14:47:49] "GET /api/V1.0/images_codes/cee07f95-18c5-40a7-ab17-261e1c1afea9 HTTP/1.1" 200 -
INFO _internal.py:88 127.0.0.1 - - [06/Jun/2019 14:47:50] "GET /api/V1.0/images_codes/5181598d-3c38-4558-a090-c29ba1b418d1 HTTP/1.1" 200 -
INFO _internal.py:88 127.0.0.1 - - [06/Jun/2019 14:47:51] "GET /api/V1.0/images_codes/c60ab9a9-1eae-47c2-b2b4-2259643335dd HTTP/1.1" 200 -
INFO _internal.py:88 127.0.0.1 - - [06/Jun/2019 14:47:59] "GET /api/V1.0/images_codes/f7db13b7-7735-4868-8e2b-0c3a3915afc8 HTTP/1.1" 200 -
